Failed to process Do Not Use: Unable to execute algorithm
Could not load source layer for INPUT: invalid value
Traceback (most recent call last):
  File "/home/timlinux/.local/share/QGIS/QGIS3/profiles/GEEST2/python/plugins/geest/core/workflows/workflow_base.py", line 240, in execute
    area_raster = self._subset_raster_layer(
                  ^^^^^^^^^^^^^^^^^^^^^^^^^^
  File "/home/timlinux/.local/share/QGIS/QGIS3/profiles/GEEST2/python/plugins/geest/core/workflows/workflow_base.py", line 394, in _subset_raster_layer
    aoi = processing.run(
          ^^^^^^^^^^^^^^^
  File "/nix/store/klsdmdrqkafiqhgcmvryqy4zli1ksxh2-qgis-unwrapped-3.38.3/share/qgis/python/plugins/processing/tools/general.py", line 109, in run
    return Processing.runAlgorithm(algOrName, parameters, onFinish, feedback, context)
           ^^^^^^^^^^^^^^^^^^^^^^^^^^^^^^^^^^^^^^^^^^^^^^^^^^^^^^^^^^^^^^^^^^^^^^^^^^^
  File "/nix/store/klsdmdrqkafiqhgcmvryqy4zli1ksxh2-qgis-unwrapped-3.38.3/share/qgis/python/plugins/processing/core/Processing.py", line 186, in runAlgorithm
    raise QgsProcessingException(msg)
_core.QgsProcessingException: Unable to execute algorithm
Could not load source layer for INPUT: invalid value
